<?xml version="1.0" ?>
<robot name="FrogBot2_top-FrogBot2-y-2_bottom-FrogBot2-y-2">

<material name="pla_5_percent_infill">
  <color rgba="0.700 0.700 0.700 1.000"/>
</material>

<link name="base_link">
  <inertial>
    <origin xyz="0 0 0" rpy="0 0 0"/>
    <mass value="1.3341577719423"/>
    <inertia ixx="0.0046797925109551535" iyy="0.011134478382956134" izz="0.010477176548232365" ixy="0.00012495104989682066" iyz="8.213962567094231e-05" ixz="-0.002474445058077273"/>
  </inertial>
  <visual>
    <origin xyz="0 0 0" rpy="0 0 0"/>
    <geometry>
      <mesh filename="simple_meshes/base_link.stl" scale="0.001 0.001 0.001"/>
    </geometry>
    <material name="pla_5_percent_infill"/>
  </visual>
  <collision>
    <origin xyz="0 0 0" rpy="0 0 0"/>
    <geometry>
      <mesh filename="simple_meshes/base_link.stl" scale="0.001 0.001 0.001"/>
    </geometry>
  </collision>
</link>

<link name="body_1_0_1">
  <inertial>
    <origin xyz="-0.053395 -0.09218 -0.023663" rpy="0 0 0"/>
    <mass value="0.05414963928909878"/>
    <inertia ixx="7.322096398285007e-05" iyy="7.66397325665337e-05" izz="1.852062050390342e-05" ixy="-2.89712407299165e-07" iyz="5.010657402395387e-06" ixz="8.030697066409615e-06"/>
  </inertial>
  <visual>
    <origin xyz="-0.053395 -0.09218 -0.023663" rpy="0 0 0"/>
    <geometry>
      <mesh filename="simple_meshes/body_1_0_1.stl" scale="0.001 0.001 0.001"/>
    </geometry>
    <material name="pla_5_percent_infill"/>
  </visual>
  <collision>
    <origin xyz="-0.053395 -0.09218 -0.023663" rpy="0 0 0"/>
    <geometry>
      <mesh filename="simple_meshes/body_1_0_1.stl" scale="0.001 0.001 0.001"/>
    </geometry>
  </collision>
</link>

<link name="body_1_1_1">
  <inertial>
    <origin xyz="0.095032 -0.09218 0.005345" rpy="0 0 0"/>
    <mass value="0.10539053543497807"/>
    <inertia ixx="7.648656435558371e-05" iyy="0.0001430534796682749" izz="0.00010447052140463795" ixy="4.835148880669203e-06" iyz="5.2590464795311325e-06" ixz="-4.030977417903884e-05"/>
  </inertial>
  <visual>
    <origin xyz="0.095032 -0.09218 0.005345" rpy="0 0 0"/>
    <geometry>
      <mesh filename="simple_meshes/body_1_1_1.stl" scale="0.001 0.001 0.001"/>
    </geometry>
    <material name="pla_5_percent_infill"/>
  </visual>
  <collision>
    <origin xyz="0.095032 -0.09218 0.005345" rpy="0 0 0"/>
    <geometry>
      <mesh filename="simple_meshes/body_1_1_1.stl" scale="0.001 0.001 0.001"/>
    </geometry>
  </collision>
</link>

<link name="body_1_2_1">
  <inertial>
    <origin xyz="-0.041549 0.09218 -0.043945" rpy="0 0 0"/>
    <mass value="0.06269270497452402"/>
    <inertia ixx="0.0001274523522902082" iyy="0.00013273599338279397" izz="2.9663636528539598e-05" ixy="1.6049821966907267e-06" iyz="-1.789621160224474e-05" ixz="1.923788717101208e-05"/>
  </inertial>
  <visual>
    <origin xyz="-0.041549 0.09218 -0.043945" rpy="0 0 0"/>
    <geometry>
      <mesh filename="simple_meshes/body_1_2_1.stl" scale="0.001 0.001 0.001"/>
    </geometry>
    <material name="pla_5_percent_infill"/>
  </visual>
  <collision>
    <origin xyz="-0.041549 0.09218 -0.043945" rpy="0 0 0"/>
    <geometry>
      <mesh filename="simple_meshes/body_1_2_1.stl" scale="0.001 0.001 0.001"/>
    </geometry>
  </collision>
</link>

<link name="body_1_3_1">
  <inertial>
    <origin xyz="0.087142 0.09218 -0.003397" rpy="0 0 0"/>
    <mass value="0.10787180234964276"/>
    <inertia ixx="7.886455923860084e-05" iyy="0.00014385653190250548" izz="0.0001048913590200179" ixy="-7.808333796017293e-06" iyz="-5.332847926788661e-06" ixz="-4.051559471153574e-05"/>
  </inertial>
  <visual>
    <origin xyz="0.087142 0.09218 -0.003397" rpy="0 0 0"/>
    <geometry>
      <mesh filename="simple_meshes/body_1_3_1.stl" scale="0.001 0.001 0.001"/>
    </geometry>
    <material name="pla_5_percent_infill"/>
  </visual>
  <collision>
    <origin xyz="0.087142 0.09218 -0.003397" rpy="0 0 0"/>
    <geometry>
      <mesh filename="simple_meshes/body_1_3_1.stl" scale="0.001 0.001 0.001"/>
    </geometry>
  </collision>
</link>

<link name="body_2_0_1">
  <inertial>
    <origin xyz="-0.065654 -0.139685 0.104558" rpy="0 0 0"/>
    <mass value="0.10406700997069096"/>
    <inertia ixx="0.00011346126229997647" iyy="0.00012540832924920302" izz="0.00018991199658074552" ixy="-1.0599562162534864e-05" iyz="5.623529840863197e-06" ixz="6.012270217499102e-06"/>
  </inertial>
  <visual>
    <origin xyz="-0.065654 -0.139685 0.104558" rpy="0 0 0"/>
    <geometry>
      <mesh filename="simple_meshes/body_2_0_1.stl" scale="0.001 0.001 0.001"/>
    </geometry>
    <material name="pla_5_percent_infill"/>
  </visual>
  <collision>
    <origin xyz="-0.065654 -0.139685 0.104558" rpy="0 0 0"/>
    <geometry>
      <mesh filename="simple_meshes/body_2_0_1.stl" scale="0.001 0.001 0.001"/>
    </geometry>
  </collision>
</link>

<link name="body_2_1_1">
  <inertial>
    <origin xyz="0.15751 -0.143533 0.104558" rpy="0 0 0"/>
    <mass value="0.0838339036483167"/>
    <inertia ixx="7.079126809306138e-05" iyy="8.554588669685333e-05" izz="9.618263412858666e-05" ixy="-1.6466551472772532e-07" iyz="1.9491246345120904e-05" ixz="1.100508674867131e-05"/>
  </inertial>
  <visual>
    <origin xyz="0.15751 -0.143533 0.104558" rpy="0 0 0"/>
    <geometry>
      <mesh filename="simple_meshes/body_2_1_1.stl" scale="0.001 0.001 0.001"/>
    </geometry>
    <material name="pla_5_percent_infill"/>
  </visual>
  <collision>
    <origin xyz="0.15751 -0.143533 0.104558" rpy="0 0 0"/>
    <geometry>
      <mesh filename="simple_meshes/body_2_1_1.stl" scale="0.001 0.001 0.001"/>
    </geometry>
  </collision>
</link>

<link name="body_2_2_1">
  <inertial>
    <origin xyz="-0.061161 0.145934 0.104558" rpy="0 0 0"/>
    <mass value="0.10170962552979187"/>
    <inertia ixx="0.00011361666083858392" iyy="0.00012234015262982357" izz="0.000189771339919756" ixy="1.1740307942443781e-05" iyz="-3.1636338973235582e-06" ixz="3.0916583550935194e-06"/>
  </inertial>
  <visual>
    <origin xyz="-0.061161 0.145934 0.104558" rpy="0 0 0"/>
    <geometry>
      <mesh filename="simple_meshes/body_2_2_1.stl" scale="0.001 0.001 0.001"/>
    </geometry>
    <material name="pla_5_percent_infill"/>
  </visual>
  <collision>
    <origin xyz="-0.061161 0.145934 0.104558" rpy="0 0 0"/>
    <geometry>
      <mesh filename="simple_meshes/body_2_2_1.stl" scale="0.001 0.001 0.001"/>
    </geometry>
  </collision>
</link>

<link name="body_2_3_1">
  <inertial>
    <origin xyz="0.160089 0.145768 0.104558" rpy="0 0 0"/>
    <mass value="0.07875681307487732"/>
    <inertia ixx="7.258512439480523e-05" iyy="8.114153741713755e-05" izz="9.064756746616316e-05" ixy="-5.987692897877796e-07" iyz="-2.1021696683060174e-05" ixz="1.4471384925871834e-05"/>
  </inertial>
  <visual>
    <origin xyz="0.160089 0.145768 0.104558" rpy="0 0 0"/>
    <geometry>
      <mesh filename="simple_meshes/body_2_3_1.stl" scale="0.001 0.001 0.001"/>
    </geometry>
    <material name="pla_5_percent_infill"/>
  </visual>
  <collision>
    <origin xyz="0.160089 0.145768 0.104558" rpy="0 0 0"/>
    <geometry>
      <mesh filename="simple_meshes/body_2_3_1.stl" scale="0.001 0.001 0.001"/>
    </geometry>
  </collision>
</link>

<joint name="joint_1_0" type="revolute">
  <origin xyz="0.053395 0.09218 0.023663" rpy="0 0 0"/>
  <parent link="base_link"/>
  <child link="body_1_0_1"/>
  <axis xyz="0.0 0.0 -1.0"/>
  <limit upper="1.2" lower="-1.2" effort="3.8" velocity="5.4"/>
</joint>
<transmission name="joint_1_0_tran">
  <type>transmission_interface/SimpleTransmission</type>
  <joint name="joint_1_0">
    <hardwareInterface>PositionJointInterface</hardwareInterface>
  </joint>
  <actuator name="joint_1_0_actr">
    <hardwareInterface>PositionJointInterface</hardwareInterface>
    <mechanicalReduction>1</mechanicalReduction>
  </actuator>
</transmission>

<joint name="joint_1_1" type="revolute">
  <origin xyz="-0.095032 0.09218 -0.005345" rpy="0 0 0"/>
  <parent link="base_link"/>
  <child link="body_1_1_1"/>
  <axis xyz="0.0 0.0 -1.0"/>
  <limit upper="1.2" lower="-1.2" effort="3.8" velocity="5.4"/>
</joint>
<transmission name="joint_1_1_tran">
  <type>transmission_interface/SimpleTransmission</type>
  <joint name="joint_1_1">
    <hardwareInterface>PositionJointInterface</hardwareInterface>
  </joint>
  <actuator name="joint_1_1_actr">
    <hardwareInterface>PositionJointInterface</hardwareInterface>
    <mechanicalReduction>1</mechanicalReduction>
  </actuator>
</transmission>

<joint name="joint_1_2" type="revolute">
  <origin xyz="0.041549 -0.09218 0.043945" rpy="0 0 0"/>
  <parent link="base_link"/>
  <child link="body_1_2_1"/>
  <axis xyz="0.0 0.0 -1.0"/>
  <limit upper="1.2" lower="-1.2" effort="3.8" velocity="5.4"/>
</joint>
<transmission name="joint_1_2_tran">
  <type>transmission_interface/SimpleTransmission</type>
  <joint name="joint_1_2">
    <hardwareInterface>PositionJointInterface</hardwareInterface>
  </joint>
  <actuator name="joint_1_2_actr">
    <hardwareInterface>PositionJointInterface</hardwareInterface>
    <mechanicalReduction>1</mechanicalReduction>
  </actuator>
</transmission>

<joint name="joint_1_3" type="revolute">
  <origin xyz="-0.087142 -0.09218 0.003397" rpy="0 0 0"/>
  <parent link="base_link"/>
  <child link="body_1_3_1"/>
  <axis xyz="0.0 0.0 -1.0"/>
  <limit upper="1.2" lower="-1.2" effort="3.8" velocity="5.4"/>
</joint>
<transmission name="joint_1_3_tran">
  <type>transmission_interface/SimpleTransmission</type>
  <joint name="joint_1_3">
    <hardwareInterface>PositionJointInterface</hardwareInterface>
  </joint>
  <actuator name="joint_1_3_actr">
    <hardwareInterface>PositionJointInterface</hardwareInterface>
    <mechanicalReduction>1</mechanicalReduction>
  </actuator>
</transmission>

<joint name="joint_2_0" type="revolute">
  <origin xyz="0.012259 0.047505 -0.128221" rpy="0 0 0"/>
  <parent link="body_1_0_1"/>
  <child link="body_2_0_1"/>
  <axis xyz="0.0 1.0 0.0"/>
  <limit upper="1.2" lower="-1.2" effort="3.8" velocity="5.4"/>
</joint>
<transmission name="joint_2_0_tran">
  <type>transmission_interface/SimpleTransmission</type>
  <joint name="joint_2_0">
    <hardwareInterface>PositionJointInterface</hardwareInterface>
  </joint>
  <actuator name="joint_2_0_actr">
    <hardwareInterface>PositionJointInterface</hardwareInterface>
    <mechanicalReduction>1</mechanicalReduction>
  </actuator>
</transmission>

<joint name="joint_2_1" type="revolute">
  <origin xyz="-0.062478 0.051353 -0.099213" rpy="0 0 0"/>
  <parent link="body_1_1_1"/>
  <child link="body_2_1_1"/>
  <axis xyz="0.0 1.0 0.0"/>
  <limit upper="1.2" lower="-1.2" effort="3.8" velocity="5.4"/>
</joint>
<transmission name="joint_2_1_tran">
  <type>transmission_interface/SimpleTransmission</type>
  <joint name="joint_2_1">
    <hardwareInterface>PositionJointInterface</hardwareInterface>
  </joint>
  <actuator name="joint_2_1_actr">
    <hardwareInterface>PositionJointInterface</hardwareInterface>
    <mechanicalReduction>1</mechanicalReduction>
  </actuator>
</transmission>

<joint name="joint_2_2" type="revolute">
  <origin xyz="0.019612 -0.053754 -0.148503" rpy="0 0 0"/>
  <parent link="body_1_2_1"/>
  <child link="body_2_2_1"/>
  <axis xyz="0.0 1.0 0.0"/>
  <limit upper="1.2" lower="-1.2" effort="3.8" velocity="5.4"/>
</joint>
<transmission name="joint_2_2_tran">
  <type>transmission_interface/SimpleTransmission</type>
  <joint name="joint_2_2">
    <hardwareInterface>PositionJointInterface</hardwareInterface>
  </joint>
  <actuator name="joint_2_2_actr">
    <hardwareInterface>PositionJointInterface</hardwareInterface>
    <mechanicalReduction>1</mechanicalReduction>
  </actuator>
</transmission>

<joint name="joint_2_3" type="revolute">
  <origin xyz="-0.072947 -0.053588 -0.107955" rpy="0 0 0"/>
  <parent link="body_1_3_1"/>
  <child link="body_2_3_1"/>
  <axis xyz="0.0 1.0 0.0"/>
  <limit upper="1.2" lower="-1.2" effort="3.8" velocity="5.4"/>
</joint>
<transmission name="joint_2_3_tran">
  <type>transmission_interface/SimpleTransmission</type>
  <joint name="joint_2_3">
    <hardwareInterface>PositionJointInterface</hardwareInterface>
  </joint>
  <actuator name="joint_2_3_actr">
    <hardwareInterface>PositionJointInterface</hardwareInterface>
    <mechanicalReduction>1</mechanicalReduction>
  </actuator>
</transmission>

</robot>
