<?xml version="1.0" ?>
<robot name="FrogBot3_top-FrogBot3-y-8_bottom-FrogBot3-y-8">

<material name="pla_5_percent_infill">
  <color rgba="0.700 0.700 0.700 1.000"/>
</material>

<link name="base_link">
  <inertial>
    <origin xyz="0 0 0" rpy="0 0 0"/>
    <mass value="1.5419899792307459"/>
    <inertia ixx="0.0054836076661745285" iyy="0.013703915460827342" izz="0.013742849788882953" ixy="5.961000823851627e-05" iyz="4.9944941207841843e-05" ixz="-0.0023657822822012154"/>
  </inertial>
  <visual>
    <origin xyz="0 0 0" rpy="0 0 0"/>
    <geometry>
      <mesh filename="simple_meshes/base_link.stl" scale="0.001 0.001 0.001"/>
    </geometry>
    <material name="pla_5_percent_infill"/>
  </visual>
  <collision>
    <origin xyz="0 0 0" rpy="0 0 0"/>
    <geometry>
      <mesh filename="simple_meshes/base_link.stl" scale="0.001 0.001 0.001"/>
    </geometry>
  </collision>
</link>

<link name="body_1_0_1">
  <inertial>
    <origin xyz="-0.065859 -0.113451 -0.001976" rpy="0 0 0"/>
    <mass value="0.05564796934521337"/>
    <inertia ixx="6.5836224945229e-05" iyy="8.403761047891145e-05" izz="3.0625960998279704e-05" ixy="3.8020194863741183e-06" iyz="5.45925674484552e-06" ixz="-2.057872433246802e-05"/>
  </inertial>
  <visual>
    <origin xyz="-0.065859 -0.113451 -0.001976" rpy="0 0 0"/>
    <geometry>
      <mesh filename="simple_meshes/body_1_0_1.stl" scale="0.001 0.001 0.001"/>
    </geometry>
    <material name="pla_5_percent_infill"/>
  </visual>
  <collision>
    <origin xyz="-0.065859 -0.113451 -0.001976" rpy="0 0 0"/>
    <geometry>
      <mesh filename="simple_meshes/body_1_0_1.stl" scale="0.001 0.001 0.001"/>
    </geometry>
  </collision>
</link>

<link name="body_1_1_1">
  <inertial>
    <origin xyz="0.083929 -0.113451 -0.010696" rpy="0 0 0"/>
    <mass value="0.08591098884425104"/>
    <inertia ixx="9.804670326154239e-05" iyy="0.00014699258473094496" izz="6.898786735200831e-05" ixy="7.039455739848771e-06" iyz="1.3495769246966668e-05" ixz="-3.4457566977377915e-05"/>
  </inertial>
  <visual>
    <origin xyz="0.083929 -0.113451 -0.010696" rpy="0 0 0"/>
    <geometry>
      <mesh filename="simple_meshes/body_1_1_1.stl" scale="0.001 0.001 0.001"/>
    </geometry>
    <material name="pla_5_percent_infill"/>
  </visual>
  <collision>
    <origin xyz="0.083929 -0.113451 -0.010696" rpy="0 0 0"/>
    <geometry>
      <mesh filename="simple_meshes/body_1_1_1.stl" scale="0.001 0.001 0.001"/>
    </geometry>
  </collision>
</link>

<link name="body_1_2_1">
  <inertial>
    <origin xyz="-0.060736 0.113451 -0.005366" rpy="0 0 0"/>
    <mass value="0.057758670438018606"/>
    <inertia ixx="7.189492376115012e-05" iyy="8.867266675629569e-05" izz="3.0164958120756187e-05" ixy="-3.791997283521286e-06" iyz="-7.766277827859981e-06" ixz="-2.142010944817754e-05"/>
  </inertial>
  <visual>
    <origin xyz="-0.060736 0.113451 -0.005366" rpy="0 0 0"/>
    <geometry>
      <mesh filename="simple_meshes/body_1_2_1.stl" scale="0.001 0.001 0.001"/>
    </geometry>
    <material name="pla_5_percent_infill"/>
  </visual>
  <collision>
    <origin xyz="-0.060736 0.113451 -0.005366" rpy="0 0 0"/>
    <geometry>
      <mesh filename="simple_meshes/body_1_2_1.stl" scale="0.001 0.001 0.001"/>
    </geometry>
  </collision>
</link>

<link name="body_1_3_1">
  <inertial>
    <origin xyz="0.093982 0.113451 -0.005431" rpy="0 0 0"/>
    <mass value="0.08907603462414063"/>
    <inertia ixx="9.245987078720062e-05" iyy="0.00013278470511056406" izz="6.308070584578338e-05" ixy="-5.405113899256773e-06" iyz="-1.2187544072497325e-05" ixz="-2.554482864688322e-05"/>
  </inertial>
  <visual>
    <origin xyz="0.093982 0.113451 -0.005431" rpy="0 0 0"/>
    <geometry>
      <mesh filename="simple_meshes/body_1_3_1.stl" scale="0.001 0.001 0.001"/>
    </geometry>
    <material name="pla_5_percent_infill"/>
  </visual>
  <collision>
    <origin xyz="0.093982 0.113451 -0.005431" rpy="0 0 0"/>
    <geometry>
      <mesh filename="simple_meshes/body_1_3_1.stl" scale="0.001 0.001 0.001"/>
    </geometry>
  </collision>
</link>

<link name="body_2_0_1">
  <inertial>
    <origin xyz="-0.026166 -0.164707 0.122895" rpy="0 0 0"/>
    <mass value="0.11666822220270685"/>
    <inertia ixx="0.0001408532731485227" iyy="0.0002702862367995676" izz="0.00021232104429767893" ixy="3.3064330777685374e-06" iyz="-5.086843345917472e-06" ixz="0.00010384002372624017"/>
  </inertial>
  <visual>
    <origin xyz="-0.026166 -0.164707 0.122895" rpy="0 0 0"/>
    <geometry>
      <mesh filename="simple_meshes/body_2_0_1.stl" scale="0.001 0.001 0.001"/>
    </geometry>
    <material name="pla_5_percent_infill"/>
  </visual>
  <collision>
    <origin xyz="-0.026166 -0.164707 0.122895" rpy="0 0 0"/>
    <geometry>
      <mesh filename="simple_meshes/body_2_0_1.stl" scale="0.001 0.001 0.001"/>
    </geometry>
  </collision>
</link>

<link name="body_2_1_1">
  <inertial>
    <origin xyz="0.127747 -0.174737 0.122895" rpy="0 0 0"/>
    <mass value="0.09265973011828019"/>
    <inertia ixx="9.987522574384216e-05" iyy="0.00015219404165151777" izz="0.00011026855347317241" ixy="-1.0284526946529107e-05" iyz="5.546956964549207e-06" ixz="5.775615041645485e-05"/>
  </inertial>
  <visual>
    <origin xyz="0.127747 -0.174737 0.122895" rpy="0 0 0"/>
    <geometry>
      <mesh filename="simple_meshes/body_2_1_1.stl" scale="0.001 0.001 0.001"/>
    </geometry>
    <material name="pla_5_percent_infill"/>
  </visual>
  <collision>
    <origin xyz="0.127747 -0.174737 0.122895" rpy="0 0 0"/>
    <geometry>
      <mesh filename="simple_meshes/body_2_1_1.stl" scale="0.001 0.001 0.001"/>
    </geometry>
  </collision>
</link>

<link name="body_2_2_1">
  <inertial>
    <origin xyz="-0.021708 0.167525 0.122895" rpy="0 0 0"/>
    <mass value="0.11450332207854122"/>
    <inertia ixx="0.00013835949162054224" iyy="0.0002657025387735835" izz="0.00020755811914872392" ixy="2.8295613783704213e-06" iyz="-2.1426722262470055e-06" ixz="0.00010272649961498483"/>
  </inertial>
  <visual>
    <origin xyz="-0.021708 0.167525 0.122895" rpy="0 0 0"/>
    <geometry>
      <mesh filename="simple_meshes/body_2_2_1.stl" scale="0.001 0.001 0.001"/>
    </geometry>
    <material name="pla_5_percent_infill"/>
  </visual>
  <collision>
    <origin xyz="-0.021708 0.167525 0.122895" rpy="0 0 0"/>
    <geometry>
      <mesh filename="simple_meshes/body_2_2_1.stl" scale="0.001 0.001 0.001"/>
    </geometry>
  </collision>
</link>

<link name="body_2_3_1">
  <inertial>
    <origin xyz="0.128136 0.172985 0.122895" rpy="0 0 0"/>
    <mass value="0.08762500115892546"/>
    <inertia ixx="9.83623069934136e-05" iyy="0.00014222371183687278" izz="0.00010712443867612982" ixy="8.457859211246982e-06" iyz="-6.993147784279015e-06" ixz="5.2715166949621715e-05"/>
  </inertial>
  <visual>
    <origin xyz="0.128136 0.172985 0.122895" rpy="0 0 0"/>
    <geometry>
      <mesh filename="simple_meshes/body_2_3_1.stl" scale="0.001 0.001 0.001"/>
    </geometry>
    <material name="pla_5_percent_infill"/>
  </visual>
  <collision>
    <origin xyz="0.128136 0.172985 0.122895" rpy="0 0 0"/>
    <geometry>
      <mesh filename="simple_meshes/body_2_3_1.stl" scale="0.001 0.001 0.001"/>
    </geometry>
  </collision>
</link>

<joint name="joint_1_0" type="revolute">
  <origin xyz="0.065859 0.113451 0.001976" rpy="0 0 0"/>
  <parent link="base_link"/>
  <child link="body_1_0_1"/>
  <axis xyz="0.0 0.0 -1.0"/>
  <limit upper="1.2" lower="-1.2" effort="3.8" velocity="5.4"/>
</joint>
<transmission name="joint_1_0_tran">
  <type>transmission_interface/SimpleTransmission</type>
  <joint name="joint_1_0">
    <hardwareInterface>PositionJointInterface</hardwareInterface>
  </joint>
  <actuator name="joint_1_0_actr">
    <hardwareInterface>PositionJointInterface</hardwareInterface>
    <mechanicalReduction>1</mechanicalReduction>
  </actuator>
</transmission>

<joint name="joint_1_1" type="revolute">
  <origin xyz="-0.083929 0.113451 0.010696" rpy="0 0 0"/>
  <parent link="base_link"/>
  <child link="body_1_1_1"/>
  <axis xyz="0.0 0.0 -1.0"/>
  <limit upper="1.2" lower="-1.2" effort="3.8" velocity="5.4"/>
</joint>
<transmission name="joint_1_1_tran">
  <type>transmission_interface/SimpleTransmission</type>
  <joint name="joint_1_1">
    <hardwareInterface>PositionJointInterface</hardwareInterface>
  </joint>
  <actuator name="joint_1_1_actr">
    <hardwareInterface>PositionJointInterface</hardwareInterface>
    <mechanicalReduction>1</mechanicalReduction>
  </actuator>
</transmission>

<joint name="joint_1_2" type="revolute">
  <origin xyz="0.060736 -0.113451 0.005366" rpy="0 0 0"/>
  <parent link="base_link"/>
  <child link="body_1_2_1"/>
  <axis xyz="0.0 0.0 -1.0"/>
  <limit upper="1.2" lower="-1.2" effort="3.8" velocity="5.4"/>
</joint>
<transmission name="joint_1_2_tran">
  <type>transmission_interface/SimpleTransmission</type>
  <joint name="joint_1_2">
    <hardwareInterface>PositionJointInterface</hardwareInterface>
  </joint>
  <actuator name="joint_1_2_actr">
    <hardwareInterface>PositionJointInterface</hardwareInterface>
    <mechanicalReduction>1</mechanicalReduction>
  </actuator>
</transmission>

<joint name="joint_1_3" type="revolute">
  <origin xyz="-0.093982 -0.113451 0.005431" rpy="0 0 0"/>
  <parent link="base_link"/>
  <child link="body_1_3_1"/>
  <axis xyz="0.0 0.0 -1.0"/>
  <limit upper="1.2" lower="-1.2" effort="3.8" velocity="5.4"/>
</joint>
<transmission name="joint_1_3_tran">
  <type>transmission_interface/SimpleTransmission</type>
  <joint name="joint_1_3">
    <hardwareInterface>PositionJointInterface</hardwareInterface>
  </joint>
  <actuator name="joint_1_3_actr">
    <hardwareInterface>PositionJointInterface</hardwareInterface>
    <mechanicalReduction>1</mechanicalReduction>
  </actuator>
</transmission>

<joint name="joint_2_0" type="revolute">
  <origin xyz="-0.039693 0.051256 -0.124871" rpy="0 0 0"/>
  <parent link="body_1_0_1"/>
  <child link="body_2_0_1"/>
  <axis xyz="0.0 1.0 0.0"/>
  <limit upper="1.2" lower="-1.2" effort="3.8" velocity="5.4"/>
</joint>
<transmission name="joint_2_0_tran">
  <type>transmission_interface/SimpleTransmission</type>
  <joint name="joint_2_0">
    <hardwareInterface>PositionJointInterface</hardwareInterface>
  </joint>
  <actuator name="joint_2_0_actr">
    <hardwareInterface>PositionJointInterface</hardwareInterface>
    <mechanicalReduction>1</mechanicalReduction>
  </actuator>
</transmission>

<joint name="joint_2_1" type="revolute">
  <origin xyz="-0.043818 0.061286 -0.133591" rpy="0 0 0"/>
  <parent link="body_1_1_1"/>
  <child link="body_2_1_1"/>
  <axis xyz="0.0 1.0 0.0"/>
  <limit upper="1.2" lower="-1.2" effort="3.8" velocity="5.4"/>
</joint>
<transmission name="joint_2_1_tran">
  <type>transmission_interface/SimpleTransmission</type>
  <joint name="joint_2_1">
    <hardwareInterface>PositionJointInterface</hardwareInterface>
  </joint>
  <actuator name="joint_2_1_actr">
    <hardwareInterface>PositionJointInterface</hardwareInterface>
    <mechanicalReduction>1</mechanicalReduction>
  </actuator>
</transmission>

<joint name="joint_2_2" type="revolute">
  <origin xyz="-0.039028 -0.054074 -0.128261" rpy="0 0 0"/>
  <parent link="body_1_2_1"/>
  <child link="body_2_2_1"/>
  <axis xyz="0.0 1.0 0.0"/>
  <limit upper="1.2" lower="-1.2" effort="3.8" velocity="5.4"/>
</joint>
<transmission name="joint_2_2_tran">
  <type>transmission_interface/SimpleTransmission</type>
  <joint name="joint_2_2">
    <hardwareInterface>PositionJointInterface</hardwareInterface>
  </joint>
  <actuator name="joint_2_2_actr">
    <hardwareInterface>PositionJointInterface</hardwareInterface>
    <mechanicalReduction>1</mechanicalReduction>
  </actuator>
</transmission>

<joint name="joint_2_3" type="revolute">
  <origin xyz="-0.034154 -0.059534 -0.128326" rpy="0 0 0"/>
  <parent link="body_1_3_1"/>
  <child link="body_2_3_1"/>
  <axis xyz="0.0 1.0 0.0"/>
  <limit upper="1.2" lower="-1.2" effort="3.8" velocity="5.4"/>
</joint>
<transmission name="joint_2_3_tran">
  <type>transmission_interface/SimpleTransmission</type>
  <joint name="joint_2_3">
    <hardwareInterface>PositionJointInterface</hardwareInterface>
  </joint>
  <actuator name="joint_2_3_actr">
    <hardwareInterface>PositionJointInterface</hardwareInterface>
    <mechanicalReduction>1</mechanicalReduction>
  </actuator>
</transmission>

</robot>
