<?xml version="1.0" ?>
<robot name="FrogBot3_top-FrogBot3-y-4_bottom-FrogBot3-y-4">

<material name="pla_5_percent_infill">
  <color rgba="0.700 0.700 0.700 1.000"/>
</material>

<link name="base_link">
  <inertial>
    <origin xyz="0 0 0" rpy="0 0 0"/>
    <mass value="1.5419899792307459"/>
    <inertia ixx="0.0054836076661745285" iyy="0.013703915460827342" izz="0.013742849788882953" ixy="5.961000823851627e-05" iyz="4.9944941207841843e-05" ixz="-0.0023657822822012154"/>
  </inertial>
  <visual>
    <origin xyz="0 0 0" rpy="0 0 0"/>
    <geometry>
      <mesh filename="simple_meshes/base_link.stl" scale="0.001 0.001 0.001"/>
    </geometry>
    <material name="pla_5_percent_infill"/>
  </visual>
  <collision>
    <origin xyz="0 0 0" rpy="0 0 0"/>
    <geometry>
      <mesh filename="simple_meshes/base_link.stl" scale="0.001 0.001 0.001"/>
    </geometry>
  </collision>
</link>

<link name="body_1_0_1">
  <inertial>
    <origin xyz="-0.065859 -0.113451 -0.001976" rpy="0 0 0"/>
    <mass value="0.04523021254123009"/>
    <inertia ixx="3.9696458151552375e-05" iyy="5.579205294275303e-05" izz="2.732350911470124e-05" ixy="3.3726491315899188e-06" iyz="4.073691839222006e-06" ixz="-1.5722319123818282e-05"/>
  </inertial>
  <visual>
    <origin xyz="-0.065859 -0.113451 -0.001976" rpy="0 0 0"/>
    <geometry>
      <mesh filename="simple_meshes/body_1_0_1.stl" scale="0.001 0.001 0.001"/>
    </geometry>
    <material name="pla_5_percent_infill"/>
  </visual>
  <collision>
    <origin xyz="-0.065859 -0.113451 -0.001976" rpy="0 0 0"/>
    <geometry>
      <mesh filename="simple_meshes/body_1_0_1.stl" scale="0.001 0.001 0.001"/>
    </geometry>
  </collision>
</link>

<link name="body_1_1_1">
  <inertial>
    <origin xyz="0.083929 -0.113451 -0.010696" rpy="0 0 0"/>
    <mass value="0.06880135852072712"/>
    <inertia ixx="5.903294688255011e-05" iyy="9.920510761012025e-05" izz="5.809906075330499e-05" ixy="6.571233818870436e-06" iyz="1.0348457800982863e-05" ixz="-2.6935314584204374e-05"/>
  </inertial>
  <visual>
    <origin xyz="0.083929 -0.113451 -0.010696" rpy="0 0 0"/>
    <geometry>
      <mesh filename="simple_meshes/body_1_1_1.stl" scale="0.001 0.001 0.001"/>
    </geometry>
    <material name="pla_5_percent_infill"/>
  </visual>
  <collision>
    <origin xyz="0.083929 -0.113451 -0.010696" rpy="0 0 0"/>
    <geometry>
      <mesh filename="simple_meshes/body_1_1_1.stl" scale="0.001 0.001 0.001"/>
    </geometry>
  </collision>
</link>

<link name="body_1_2_1">
  <inertial>
    <origin xyz="-0.060736 0.113451 -0.005366" rpy="0 0 0"/>
    <mass value="0.047283513782958454"/>
    <inertia ixx="4.389693884759025e-05" iyy="5.894789943221274e-05" izz="2.7223097277075115e-05" ixy="-3.5575507381732803e-06" iyz="-5.881686172434092e-06" ixz="-1.65168600868911e-05"/>
  </inertial>
  <visual>
    <origin xyz="-0.060736 0.113451 -0.005366" rpy="0 0 0"/>
    <geometry>
      <mesh filename="simple_meshes/body_1_2_1.stl" scale="0.001 0.001 0.001"/>
    </geometry>
    <material name="pla_5_percent_infill"/>
  </visual>
  <collision>
    <origin xyz="-0.060736 0.113451 -0.005366" rpy="0 0 0"/>
    <geometry>
      <mesh filename="simple_meshes/body_1_2_1.stl" scale="0.001 0.001 0.001"/>
    </geometry>
  </collision>
</link>

<link name="body_1_3_1">
  <inertial>
    <origin xyz="0.093982 0.113451 -0.005431" rpy="0 0 0"/>
    <mass value="0.06990327652718731"/>
    <inertia ixx="5.4338542721558145e-05" iyy="8.657500704453204e-05" izz="5.165373225145351e-05" ixy="-4.827868016864766e-06" iyz="-9.13482158717996e-06" ixz="-1.9810365161136993e-05"/>
  </inertial>
  <visual>
    <origin xyz="0.093982 0.113451 -0.005431" rpy="0 0 0"/>
    <geometry>
      <mesh filename="simple_meshes/body_1_3_1.stl" scale="0.001 0.001 0.001"/>
    </geometry>
    <material name="pla_5_percent_infill"/>
  </visual>
  <collision>
    <origin xyz="0.093982 0.113451 -0.005431" rpy="0 0 0"/>
    <geometry>
      <mesh filename="simple_meshes/body_1_3_1.stl" scale="0.001 0.001 0.001"/>
    </geometry>
  </collision>
</link>

<link name="body_2_0_1">
  <inertial>
    <origin xyz="-0.026166 -0.164707 0.102895" rpy="0 0 0"/>
    <mass value="0.0847492745228644"/>
    <inertia ixx="7.740216099426985e-05" iyy="0.00020995541576546758" izz="0.00020498280341185986" ixy="4.875677627074566e-06" iyz="-3.8759552899859766e-06" ixz="7.400617048070068e-05"/>
  </inertial>
  <visual>
    <origin xyz="-0.026166 -0.164707 0.102895" rpy="0 0 0"/>
    <geometry>
      <mesh filename="simple_meshes/body_2_0_1.stl" scale="0.001 0.001 0.001"/>
    </geometry>
    <material name="pla_5_percent_infill"/>
  </visual>
  <collision>
    <origin xyz="-0.026166 -0.164707 0.102895" rpy="0 0 0"/>
    <geometry>
      <mesh filename="simple_meshes/body_2_0_1.stl" scale="0.001 0.001 0.001"/>
    </geometry>
  </collision>
</link>

<link name="body_2_1_1">
  <inertial>
    <origin xyz="0.127747 -0.174737 0.102895" rpy="0 0 0"/>
    <mass value="0.07417124681819136"/>
    <inertia ixx="5.710917324846902e-05" iyy="0.00010570460246660165" izz="0.00010165059168990671" ixy="-9.388975548049825e-06" iyz="3.58451696163848e-06" ixz="3.8595480920323305e-05"/>
  </inertial>
  <visual>
    <origin xyz="0.127747 -0.174737 0.102895" rpy="0 0 0"/>
    <geometry>
      <mesh filename="simple_meshes/body_2_1_1.stl" scale="0.001 0.001 0.001"/>
    </geometry>
    <material name="pla_5_percent_infill"/>
  </visual>
  <collision>
    <origin xyz="0.127747 -0.174737 0.102895" rpy="0 0 0"/>
    <geometry>
      <mesh filename="simple_meshes/body_2_1_1.stl" scale="0.001 0.001 0.001"/>
    </geometry>
  </collision>
</link>

<link name="body_2_2_1">
  <inertial>
    <origin xyz="-0.021708 0.167525 0.102895" rpy="0 0 0"/>
    <mass value="0.0850620697412849"/>
    <inertia ixx="7.686213732371536e-05" iyy="0.00020830545349865117" izz="0.0002031925820917082" ixy="1.6062206704726967e-06" iyz="-1.1335614564663386e-06" ixz="7.31691742605449e-05"/>
  </inertial>
  <visual>
    <origin xyz="-0.021708 0.167525 0.102895" rpy="0 0 0"/>
    <geometry>
      <mesh filename="simple_meshes/body_2_2_1.stl" scale="0.001 0.001 0.001"/>
    </geometry>
    <material name="pla_5_percent_infill"/>
  </visual>
  <collision>
    <origin xyz="-0.021708 0.167525 0.102895" rpy="0 0 0"/>
    <geometry>
      <mesh filename="simple_meshes/body_2_2_1.stl" scale="0.001 0.001 0.001"/>
    </geometry>
  </collision>
</link>

<link name="body_2_3_1">
  <inertial>
    <origin xyz="0.128136 0.172985 0.102895" rpy="0 0 0"/>
    <mass value="0.0715746486443258"/>
    <inertia ixx="5.9022775953296996e-05" iyy="9.928317724688853e-05" izz="0.00010004935171188927" ixy="7.567039896411252e-06" iyz="-4.6331607226716975e-06" ixz="3.548011629787807e-05"/>
  </inertial>
  <visual>
    <origin xyz="0.128136 0.172985 0.102895" rpy="0 0 0"/>
    <geometry>
      <mesh filename="simple_meshes/body_2_3_1.stl" scale="0.001 0.001 0.001"/>
    </geometry>
    <material name="pla_5_percent_infill"/>
  </visual>
  <collision>
    <origin xyz="0.128136 0.172985 0.102895" rpy="0 0 0"/>
    <geometry>
      <mesh filename="simple_meshes/body_2_3_1.stl" scale="0.001 0.001 0.001"/>
    </geometry>
  </collision>
</link>

<joint name="joint_1_0" type="revolute">
  <origin xyz="0.065859 0.113451 0.001976" rpy="0 0 0"/>
  <parent link="base_link"/>
  <child link="body_1_0_1"/>
  <axis xyz="0.0 0.0 -1.0"/>
  <limit upper="1.2" lower="-1.2" effort="3.8" velocity="5.4"/>
</joint>
<transmission name="joint_1_0_tran">
  <type>transmission_interface/SimpleTransmission</type>
  <joint name="joint_1_0">
    <hardwareInterface>PositionJointInterface</hardwareInterface>
  </joint>
  <actuator name="joint_1_0_actr">
    <hardwareInterface>PositionJointInterface</hardwareInterface>
    <mechanicalReduction>1</mechanicalReduction>
  </actuator>
</transmission>

<joint name="joint_1_1" type="revolute">
  <origin xyz="-0.083929 0.113451 0.010696" rpy="0 0 0"/>
  <parent link="base_link"/>
  <child link="body_1_1_1"/>
  <axis xyz="0.0 0.0 -1.0"/>
  <limit upper="1.2" lower="-1.2" effort="3.8" velocity="5.4"/>
</joint>
<transmission name="joint_1_1_tran">
  <type>transmission_interface/SimpleTransmission</type>
  <joint name="joint_1_1">
    <hardwareInterface>PositionJointInterface</hardwareInterface>
  </joint>
  <actuator name="joint_1_1_actr">
    <hardwareInterface>PositionJointInterface</hardwareInterface>
    <mechanicalReduction>1</mechanicalReduction>
  </actuator>
</transmission>

<joint name="joint_1_2" type="revolute">
  <origin xyz="0.060736 -0.113451 0.005366" rpy="0 0 0"/>
  <parent link="base_link"/>
  <child link="body_1_2_1"/>
  <axis xyz="0.0 0.0 -1.0"/>
  <limit upper="1.2" lower="-1.2" effort="3.8" velocity="5.4"/>
</joint>
<transmission name="joint_1_2_tran">
  <type>transmission_interface/SimpleTransmission</type>
  <joint name="joint_1_2">
    <hardwareInterface>PositionJointInterface</hardwareInterface>
  </joint>
  <actuator name="joint_1_2_actr">
    <hardwareInterface>PositionJointInterface</hardwareInterface>
    <mechanicalReduction>1</mechanicalReduction>
  </actuator>
</transmission>

<joint name="joint_1_3" type="revolute">
  <origin xyz="-0.093982 -0.113451 0.005431" rpy="0 0 0"/>
  <parent link="base_link"/>
  <child link="body_1_3_1"/>
  <axis xyz="0.0 0.0 -1.0"/>
  <limit upper="1.2" lower="-1.2" effort="3.8" velocity="5.4"/>
</joint>
<transmission name="joint_1_3_tran">
  <type>transmission_interface/SimpleTransmission</type>
  <joint name="joint_1_3">
    <hardwareInterface>PositionJointInterface</hardwareInterface>
  </joint>
  <actuator name="joint_1_3_actr">
    <hardwareInterface>PositionJointInterface</hardwareInterface>
    <mechanicalReduction>1</mechanicalReduction>
  </actuator>
</transmission>

<joint name="joint_2_0" type="revolute">
  <origin xyz="-0.039693 0.051256 -0.104871" rpy="0 0 0"/>
  <parent link="body_1_0_1"/>
  <child link="body_2_0_1"/>
  <axis xyz="0.0 1.0 0.0"/>
  <limit upper="1.2" lower="-1.2" effort="3.8" velocity="5.4"/>
</joint>
<transmission name="joint_2_0_tran">
  <type>transmission_interface/SimpleTransmission</type>
  <joint name="joint_2_0">
    <hardwareInterface>PositionJointInterface</hardwareInterface>
  </joint>
  <actuator name="joint_2_0_actr">
    <hardwareInterface>PositionJointInterface</hardwareInterface>
    <mechanicalReduction>1</mechanicalReduction>
  </actuator>
</transmission>

<joint name="joint_2_1" type="revolute">
  <origin xyz="-0.043818 0.061286 -0.113591" rpy="0 0 0"/>
  <parent link="body_1_1_1"/>
  <child link="body_2_1_1"/>
  <axis xyz="0.0 1.0 0.0"/>
  <limit upper="1.2" lower="-1.2" effort="3.8" velocity="5.4"/>
</joint>
<transmission name="joint_2_1_tran">
  <type>transmission_interface/SimpleTransmission</type>
  <joint name="joint_2_1">
    <hardwareInterface>PositionJointInterface</hardwareInterface>
  </joint>
  <actuator name="joint_2_1_actr">
    <hardwareInterface>PositionJointInterface</hardwareInterface>
    <mechanicalReduction>1</mechanicalReduction>
  </actuator>
</transmission>

<joint name="joint_2_2" type="revolute">
  <origin xyz="-0.039028 -0.054074 -0.108261" rpy="0 0 0"/>
  <parent link="body_1_2_1"/>
  <child link="body_2_2_1"/>
  <axis xyz="0.0 1.0 0.0"/>
  <limit upper="1.2" lower="-1.2" effort="3.8" velocity="5.4"/>
</joint>
<transmission name="joint_2_2_tran">
  <type>transmission_interface/SimpleTransmission</type>
  <joint name="joint_2_2">
    <hardwareInterface>PositionJointInterface</hardwareInterface>
  </joint>
  <actuator name="joint_2_2_actr">
    <hardwareInterface>PositionJointInterface</hardwareInterface>
    <mechanicalReduction>1</mechanicalReduction>
  </actuator>
</transmission>

<joint name="joint_2_3" type="revolute">
  <origin xyz="-0.034154 -0.059534 -0.108326" rpy="0 0 0"/>
  <parent link="body_1_3_1"/>
  <child link="body_2_3_1"/>
  <axis xyz="0.0 1.0 0.0"/>
  <limit upper="1.2" lower="-1.2" effort="3.8" velocity="5.4"/>
</joint>
<transmission name="joint_2_3_tran">
  <type>transmission_interface/SimpleTransmission</type>
  <joint name="joint_2_3">
    <hardwareInterface>PositionJointInterface</hardwareInterface>
  </joint>
  <actuator name="joint_2_3_actr">
    <hardwareInterface>PositionJointInterface</hardwareInterface>
    <mechanicalReduction>1</mechanicalReduction>
  </actuator>
</transmission>

</robot>
