<?xml version="1.0" ?>
<robot name="FrogBot5_top-FrogBot5-y-8_bottom-FrogBot5-y-8">

<material name="pla_5_percent_infill">
  <color rgba="0.700 0.700 0.700 1.000"/>
</material>

<link name="base_link">
  <inertial>
    <origin xyz="0 0 0" rpy="0 0 0"/>
    <mass value="1.4805118043364613"/>
    <inertia ixx="0.00519778244400068" iyy="0.011185972187213383" izz="0.012581059264896973" ixy="-0.0002102027550041139" iyz="-1.09064860282594e-05" ixz="-0.0008439426245005397"/>
  </inertial>
  <visual>
    <origin xyz="0 0 0" rpy="0 0 0"/>
    <geometry>
      <mesh filename="simple_meshes/base_link.stl" scale="0.001 0.001 0.001"/>
    </geometry>
    <material name="pla_5_percent_infill"/>
  </visual>
  <collision>
    <origin xyz="0 0 0" rpy="0 0 0"/>
    <geometry>
      <mesh filename="simple_meshes/base_link.stl" scale="0.001 0.001 0.001"/>
    </geometry>
  </collision>
</link>

<link name="body_1_0_1">
  <inertial>
    <origin xyz="-0.05492 -0.106321 -0.011198" rpy="0 0 0"/>
    <mass value="0.04232030645417784"/>
    <inertia ixx="5.3152271473521934e-05" iyy="5.6608240261008745e-05" izz="1.3158962775877562e-05" ixy="-1.196857118406381e-07" iyz="-2.3048200803218847e-06" ixz="-1.3935831772096398e-06"/>
  </inertial>
  <visual>
    <origin xyz="-0.05492 -0.106321 -0.011198" rpy="0 0 0"/>
    <geometry>
      <mesh filename="simple_meshes/body_1_0_1.stl" scale="0.001 0.001 0.001"/>
    </geometry>
    <material name="pla_5_percent_infill"/>
  </visual>
  <collision>
    <origin xyz="-0.05492 -0.106321 -0.011198" rpy="0 0 0"/>
    <geometry>
      <mesh filename="simple_meshes/body_1_0_1.stl" scale="0.001 0.001 0.001"/>
    </geometry>
  </collision>
</link>

<link name="body_1_1_1">
  <inertial>
    <origin xyz="0.058377 -0.106321 -0.025493" rpy="0 0 0"/>
    <mass value="0.06986327090095712"/>
    <inertia ixx="9.998229729012826e-05" iyy="0.00012271025781361187" izz="4.195827122367235e-05" ixy="-2.3106153026197784e-06" iyz="-1.5585408407111658e-06" ixz="-3.306414728230077e-05"/>
  </inertial>
  <visual>
    <origin xyz="0.058377 -0.106321 -0.025493" rpy="0 0 0"/>
    <geometry>
      <mesh filename="simple_meshes/body_1_1_1.stl" scale="0.001 0.001 0.001"/>
    </geometry>
    <material name="pla_5_percent_infill"/>
  </visual>
  <collision>
    <origin xyz="0.058377 -0.106321 -0.025493" rpy="0 0 0"/>
    <geometry>
      <mesh filename="simple_meshes/body_1_1_1.stl" scale="0.001 0.001 0.001"/>
    </geometry>
  </collision>
</link>

<link name="body_1_2_1">
  <inertial>
    <origin xyz="-0.053934 0.106321 -0.032331" rpy="0 0 0"/>
    <mass value="0.060816230310022416"/>
    <inertia ixx="9.320590331918601e-05" iyy="9.946374956156147e-05" izz="2.0355298293735528e-05" ixy="2.407247153977032e-07" iyz="-2.492183084878952e-07" ixz="9.01145755779249e-06"/>
  </inertial>
  <visual>
    <origin xyz="-0.053934 0.106321 -0.032331" rpy="0 0 0"/>
    <geometry>
      <mesh filename="simple_meshes/body_1_2_1.stl" scale="0.001 0.001 0.001"/>
    </geometry>
    <material name="pla_5_percent_infill"/>
  </visual>
  <collision>
    <origin xyz="-0.053934 0.106321 -0.032331" rpy="0 0 0"/>
    <geometry>
      <mesh filename="simple_meshes/body_1_2_1.stl" scale="0.001 0.001 0.001"/>
    </geometry>
  </collision>
</link>

<link name="body_1_3_1">
  <inertial>
    <origin xyz="0.057483 0.106321 -0.032919" rpy="0 0 0"/>
    <mass value="0.06765735536001237"/>
    <inertia ixx="0.00010221545801719373" iyy="0.00011989151498917306" izz="3.380777762786516e-05" ixy="-5.543396504305515e-07" iyz="-2.688434823250091e-06" ixz="-2.8277332383147292e-05"/>
  </inertial>
  <visual>
    <origin xyz="0.057483 0.106321 -0.032919" rpy="0 0 0"/>
    <geometry>
      <mesh filename="simple_meshes/body_1_3_1.stl" scale="0.001 0.001 0.001"/>
    </geometry>
    <material name="pla_5_percent_infill"/>
  </visual>
  <collision>
    <origin xyz="0.057483 0.106321 -0.032919" rpy="0 0 0"/>
    <geometry>
      <mesh filename="simple_meshes/body_1_3_1.stl" scale="0.001 0.001 0.001"/>
    </geometry>
  </collision>
</link>

<link name="body_2_0_1">
  <inertial>
    <origin xyz="-0.051784 -0.143449 0.110454" rpy="0 0 0"/>
    <mass value="0.09604299147473908"/>
    <inertia ixx="0.00013747265935670078" iyy="0.00014470425597472823" izz="9.833382761591323e-05" ixy="-4.577093931210107e-06" iyz="5.127971446438218e-06" ixz="-4.548601761460592e-06"/>
  </inertial>
  <visual>
    <origin xyz="-0.051784 -0.143449 0.110454" rpy="0 0 0"/>
    <geometry>
      <mesh filename="simple_meshes/body_2_0_1.stl" scale="0.001 0.001 0.001"/>
    </geometry>
    <material name="pla_5_percent_infill"/>
  </visual>
  <collision>
    <origin xyz="-0.051784 -0.143449 0.110454" rpy="0 0 0"/>
    <geometry>
      <mesh filename="simple_meshes/body_2_0_1.stl" scale="0.001 0.001 0.001"/>
    </geometry>
  </collision>
</link>

<link name="body_2_1_1">
  <inertial>
    <origin xyz="0.108798 -0.147527 0.110454" rpy="0 0 0"/>
    <mass value="0.1423832546538233"/>
    <inertia ixx="0.00013031222453682711" iyy="0.00015616023853373164" izz="0.0001097409221668278" ixy="-2.5988512059585064e-06" iyz="4.4015384250209455e-07" ixz="-9.719374548197192e-07"/>
  </inertial>
  <visual>
    <origin xyz="0.108798 -0.147527 0.110454" rpy="0 0 0"/>
    <geometry>
      <mesh filename="simple_meshes/body_2_1_1.stl" scale="0.001 0.001 0.001"/>
    </geometry>
    <material name="pla_5_percent_infill"/>
  </visual>
  <collision>
    <origin xyz="0.108798 -0.147527 0.110454" rpy="0 0 0"/>
    <geometry>
      <mesh filename="simple_meshes/body_2_1_1.stl" scale="0.001 0.001 0.001"/>
    </geometry>
  </collision>
</link>

<link name="body_2_2_1">
  <inertial>
    <origin xyz="-0.065031 0.147225 0.110454" rpy="0 0 0"/>
    <mass value="0.09590273321680425"/>
    <inertia ixx="0.0001350011941966692" iyy="0.00013343384231722516" izz="9.143497171969477e-05" ixy="6.060188519208605e-06" iyz="-4.506971500901902e-06" ixz="-7.818255379870393e-06"/>
  </inertial>
  <visual>
    <origin xyz="-0.065031 0.147225 0.110454" rpy="0 0 0"/>
    <geometry>
      <mesh filename="simple_meshes/body_2_2_1.stl" scale="0.001 0.001 0.001"/>
    </geometry>
    <material name="pla_5_percent_infill"/>
  </visual>
  <collision>
    <origin xyz="-0.065031 0.147225 0.110454" rpy="0 0 0"/>
    <geometry>
      <mesh filename="simple_meshes/body_2_2_1.stl" scale="0.001 0.001 0.001"/>
    </geometry>
  </collision>
</link>

<link name="body_2_3_1">
  <inertial>
    <origin xyz="0.101339 0.151086 0.110454" rpy="0 0 0"/>
    <mass value="0.15148827324235262"/>
    <inertia ixx="0.00015793498872203847" iyy="0.00019303099324881074" izz="0.00012040388724332985" ixy="1.336013918399638e-06" iyz="-5.883122309932945e-06" ixz="7.768151744746987e-06"/>
  </inertial>
  <visual>
    <origin xyz="0.101339 0.151086 0.110454" rpy="0 0 0"/>
    <geometry>
      <mesh filename="simple_meshes/body_2_3_1.stl" scale="0.001 0.001 0.001"/>
    </geometry>
    <material name="pla_5_percent_infill"/>
  </visual>
  <collision>
    <origin xyz="0.101339 0.151086 0.110454" rpy="0 0 0"/>
    <geometry>
      <mesh filename="simple_meshes/body_2_3_1.stl" scale="0.001 0.001 0.001"/>
    </geometry>
  </collision>
</link>

<joint name="joint_1_0" type="revolute">
  <origin xyz="0.05492 0.106321 0.011198" rpy="0 0 0"/>
  <parent link="base_link"/>
  <child link="body_1_0_1"/>
  <axis xyz="0.0 0.0 -1.0"/>
  <limit upper="1.2" lower="-1.2" effort="3.8" velocity="5.4"/>
</joint>
<transmission name="joint_1_0_tran">
  <type>transmission_interface/SimpleTransmission</type>
  <joint name="joint_1_0">
    <hardwareInterface>PositionJointInterface</hardwareInterface>
  </joint>
  <actuator name="joint_1_0_actr">
    <hardwareInterface>PositionJointInterface</hardwareInterface>
    <mechanicalReduction>1</mechanicalReduction>
  </actuator>
</transmission>

<joint name="joint_1_1" type="revolute">
  <origin xyz="-0.058377 0.106321 0.025493" rpy="0 0 0"/>
  <parent link="base_link"/>
  <child link="body_1_1_1"/>
  <axis xyz="0.0 0.0 -1.0"/>
  <limit upper="1.2" lower="-1.2" effort="3.8" velocity="5.4"/>
</joint>
<transmission name="joint_1_1_tran">
  <type>transmission_interface/SimpleTransmission</type>
  <joint name="joint_1_1">
    <hardwareInterface>PositionJointInterface</hardwareInterface>
  </joint>
  <actuator name="joint_1_1_actr">
    <hardwareInterface>PositionJointInterface</hardwareInterface>
    <mechanicalReduction>1</mechanicalReduction>
  </actuator>
</transmission>

<joint name="joint_1_2" type="revolute">
  <origin xyz="0.053934 -0.106321 0.032331" rpy="0 0 0"/>
  <parent link="base_link"/>
  <child link="body_1_2_1"/>
  <axis xyz="0.0 0.0 -1.0"/>
  <limit upper="1.2" lower="-1.2" effort="3.8" velocity="5.4"/>
</joint>
<transmission name="joint_1_2_tran">
  <type>transmission_interface/SimpleTransmission</type>
  <joint name="joint_1_2">
    <hardwareInterface>PositionJointInterface</hardwareInterface>
  </joint>
  <actuator name="joint_1_2_actr">
    <hardwareInterface>PositionJointInterface</hardwareInterface>
    <mechanicalReduction>1</mechanicalReduction>
  </actuator>
</transmission>

<joint name="joint_1_3" type="revolute">
  <origin xyz="-0.057483 -0.106321 0.032919" rpy="0 0 0"/>
  <parent link="base_link"/>
  <child link="body_1_3_1"/>
  <axis xyz="0.0 0.0 -1.0"/>
  <limit upper="1.2" lower="-1.2" effort="3.8" velocity="5.4"/>
</joint>
<transmission name="joint_1_3_tran">
  <type>transmission_interface/SimpleTransmission</type>
  <joint name="joint_1_3">
    <hardwareInterface>PositionJointInterface</hardwareInterface>
  </joint>
  <actuator name="joint_1_3_actr">
    <hardwareInterface>PositionJointInterface</hardwareInterface>
    <mechanicalReduction>1</mechanicalReduction>
  </actuator>
</transmission>

<joint name="joint_2_0" type="revolute">
  <origin xyz="-0.003136 0.037128 -0.121652" rpy="0 0 0"/>
  <parent link="body_1_0_1"/>
  <child link="body_2_0_1"/>
  <axis xyz="0.0 1.0 0.0"/>
  <limit upper="1.2" lower="-1.2" effort="3.8" velocity="5.4"/>
</joint>
<transmission name="joint_2_0_tran">
  <type>transmission_interface/SimpleTransmission</type>
  <joint name="joint_2_0">
    <hardwareInterface>PositionJointInterface</hardwareInterface>
  </joint>
  <actuator name="joint_2_0_actr">
    <hardwareInterface>PositionJointInterface</hardwareInterface>
    <mechanicalReduction>1</mechanicalReduction>
  </actuator>
</transmission>

<joint name="joint_2_1" type="revolute">
  <origin xyz="-0.050421 0.041206 -0.135947" rpy="0 0 0"/>
  <parent link="body_1_1_1"/>
  <child link="body_2_1_1"/>
  <axis xyz="0.0 1.0 0.0"/>
  <limit upper="1.2" lower="-1.2" effort="3.8" velocity="5.4"/>
</joint>
<transmission name="joint_2_1_tran">
  <type>transmission_interface/SimpleTransmission</type>
  <joint name="joint_2_1">
    <hardwareInterface>PositionJointInterface</hardwareInterface>
  </joint>
  <actuator name="joint_2_1_actr">
    <hardwareInterface>PositionJointInterface</hardwareInterface>
    <mechanicalReduction>1</mechanicalReduction>
  </actuator>
</transmission>

<joint name="joint_2_2" type="revolute">
  <origin xyz="0.011097 -0.040904 -0.142785" rpy="0 0 0"/>
  <parent link="body_1_2_1"/>
  <child link="body_2_2_1"/>
  <axis xyz="0.0 1.0 0.0"/>
  <limit upper="1.2" lower="-1.2" effort="3.8" velocity="5.4"/>
</joint>
<transmission name="joint_2_2_tran">
  <type>transmission_interface/SimpleTransmission</type>
  <joint name="joint_2_2">
    <hardwareInterface>PositionJointInterface</hardwareInterface>
  </joint>
  <actuator name="joint_2_2_actr">
    <hardwareInterface>PositionJointInterface</hardwareInterface>
    <mechanicalReduction>1</mechanicalReduction>
  </actuator>
</transmission>

<joint name="joint_2_3" type="revolute">
  <origin xyz="-0.043856 -0.044765 -0.143373" rpy="0 0 0"/>
  <parent link="body_1_3_1"/>
  <child link="body_2_3_1"/>
  <axis xyz="0.0 1.0 0.0"/>
  <limit upper="1.2" lower="-1.2" effort="3.8" velocity="5.4"/>
</joint>
<transmission name="joint_2_3_tran">
  <type>transmission_interface/SimpleTransmission</type>
  <joint name="joint_2_3">
    <hardwareInterface>PositionJointInterface</hardwareInterface>
  </joint>
  <actuator name="joint_2_3_actr">
    <hardwareInterface>PositionJointInterface</hardwareInterface>
    <mechanicalReduction>1</mechanicalReduction>
  </actuator>
</transmission>

</robot>
