<?xml version="1.0" ?>
<robot name="FrogBot1_top-FrogBot1-z-4_bottom-FrogBot1-z-4">

<material name="pla_5_percent_infill">
  <color rgba="0.700 0.700 0.700 1.000"/>
</material>

<link name="base_link">
  <inertial>
    <origin xyz="0 0 0" rpy="0 0 0"/>
    <mass value="1.4103143072721238"/>
    <inertia ixx="0.004671865419262023" iyy="0.01102984328633242" izz="0.011972094032648898" ixy="0.00015185420958179873" iyz="8.583160306759328e-05" ixz="-0.0012132770853355082"/>
  </inertial>
  <visual>
    <origin xyz="0 0 0" rpy="0 0 0"/>
    <geometry>
      <mesh filename="simple_meshes/base_link.stl" scale="0.001 0.001 0.001"/>
    </geometry>
    <material name="pla_5_percent_infill"/>
  </visual>
  <collision>
    <origin xyz="0 0 0" rpy="0 0 0"/>
    <geometry>
      <mesh filename="simple_meshes/base_link.stl" scale="0.001 0.001 0.001"/>
    </geometry>
  </collision>
</link>

<link name="body_1_0_1">
  <inertial>
    <origin xyz="-0.045735 -0.109621 -0.00462" rpy="0 0 0"/>
    <mass value="0.03879208926721642"/>
    <inertia ixx="3.793123772816913e-05" iyy="3.979322157933629e-05" izz="1.4336450828997824e-05" ixy="-4.3859643624897995e-07" iyz="2.889189880319427e-06" ixz="5.717862344251724e-07"/>
  </inertial>
  <visual>
    <origin xyz="-0.045735 -0.109621 -0.00462" rpy="0 0 0"/>
    <geometry>
      <mesh filename="simple_meshes/body_1_0_1.stl" scale="0.001 0.001 0.001"/>
    </geometry>
    <material name="pla_5_percent_infill"/>
  </visual>
  <collision>
    <origin xyz="-0.045735 -0.109621 -0.00462" rpy="0 0 0"/>
    <geometry>
      <mesh filename="simple_meshes/body_1_0_1.stl" scale="0.001 0.001 0.001"/>
    </geometry>
  </collision>
</link>

<link name="body_1_1_1">
  <inertial>
    <origin xyz="0.086489 -0.109621 -0.018802" rpy="0 0 0"/>
    <mass value="0.06970153782718615"/>
    <inertia ixx="7.485681053907931e-05" iyy="8.255272871749949e-05" izz="4.113204068544778e-05" ixy="5.961934677416051e-06" iyz="1.285823416582359e-05" ixz="-1.9641305613061995e-05"/>
  </inertial>
  <visual>
    <origin xyz="0.086489 -0.109621 -0.018802" rpy="0 0 0"/>
    <geometry>
      <mesh filename="simple_meshes/body_1_1_1.stl" scale="0.001 0.001 0.001"/>
    </geometry>
    <material name="pla_5_percent_infill"/>
  </visual>
  <collision>
    <origin xyz="0.086489 -0.109621 -0.018802" rpy="0 0 0"/>
    <geometry>
      <mesh filename="simple_meshes/body_1_1_1.stl" scale="0.001 0.001 0.001"/>
    </geometry>
  </collision>
</link>

<link name="body_1_2_1">
  <inertial>
    <origin xyz="-0.040267 0.109621 -0.027764" rpy="0 0 0"/>
    <mass value="0.050469668014060075"/>
    <inertia ixx="7.528927324983235e-05" iyy="7.403062543695226e-05" izz="2.248478083551877e-05" ixy="6.159399996066698e-07" iyz="-1.3278139408470096e-05" ixz="-1.79026243325607e-07"/>
  </inertial>
  <visual>
    <origin xyz="-0.040267 0.109621 -0.027764" rpy="0 0 0"/>
    <geometry>
      <mesh filename="simple_meshes/body_1_2_1.stl" scale="0.001 0.001 0.001"/>
    </geometry>
    <material name="pla_5_percent_infill"/>
  </visual>
  <collision>
    <origin xyz="-0.040267 0.109621 -0.027764" rpy="0 0 0"/>
    <geometry>
      <mesh filename="simple_meshes/body_1_2_1.stl" scale="0.001 0.001 0.001"/>
    </geometry>
  </collision>
</link>

<link name="body_1_3_1">
  <inertial>
    <origin xyz="0.090407 0.109621 -0.022193" rpy="0 0 0"/>
    <mass value="0.07051428562138756"/>
    <inertia ixx="8.234578748951582e-05" iyy="9.212021029979061e-05" izz="4.505565857923716e-05" ixy="-7.343205658714384e-06" iyz="-1.5796759604781198e-05" ixz="-2.375696135519412e-05"/>
  </inertial>
  <visual>
    <origin xyz="0.090407 0.109621 -0.022193" rpy="0 0 0"/>
    <geometry>
      <mesh filename="simple_meshes/body_1_3_1.stl" scale="0.001 0.001 0.001"/>
    </geometry>
    <material name="pla_5_percent_infill"/>
  </visual>
  <collision>
    <origin xyz="0.090407 0.109621 -0.022193" rpy="0 0 0"/>
    <geometry>
      <mesh filename="simple_meshes/body_1_3_1.stl" scale="0.001 0.001 0.001"/>
    </geometry>
  </collision>
</link>

<link name="body_2_0_1">
  <inertial>
    <origin xyz="-0.049562 -0.159797 0.095064" rpy="0 0 0"/>
    <mass value="0.10303976412850015"/>
    <inertia ixx="0.00011780316974623669" iyy="0.0001309551990743697" izz="0.00013742124003981006" ixy="-4.695988367956145e-06" iyz="-9.946031705693019e-07" ixz="3.077147483612525e-05"/>
  </inertial>
  <visual>
    <origin xyz="-0.049562 -0.159797 0.095064" rpy="0 0 0"/>
    <geometry>
      <mesh filename="simple_meshes/body_2_0_1.stl" scale="0.001 0.001 0.001"/>
    </geometry>
    <material name="pla_5_percent_infill"/>
  </visual>
  <collision>
    <origin xyz="-0.049562 -0.159797 0.095064" rpy="0 0 0"/>
    <geometry>
      <mesh filename="simple_meshes/body_2_0_1.stl" scale="0.001 0.001 0.001"/>
    </geometry>
  </collision>
</link>

<link name="body_2_1_1">
  <inertial>
    <origin xyz="0.121182 -0.173952 0.095064" rpy="0 0 0"/>
    <mass value="0.11010765378387201"/>
    <inertia ixx="0.0001253850300086453" iyy="0.0001346070861380248" izz="0.000143945008506648" ixy="-1.5131088088342e-07" iyz="1.829040436844131e-05" ixz="3.634164909816851e-05"/>
  </inertial>
  <visual>
    <origin xyz="0.121182 -0.173952 0.095064" rpy="0 0 0"/>
    <geometry>
      <mesh filename="simple_meshes/body_2_1_1.stl" scale="0.001 0.001 0.001"/>
    </geometry>
    <material name="pla_5_percent_infill"/>
  </visual>
  <collision>
    <origin xyz="0.121182 -0.173952 0.095064" rpy="0 0 0"/>
    <geometry>
      <mesh filename="simple_meshes/body_2_1_1.stl" scale="0.001 0.001 0.001"/>
    </geometry>
  </collision>
</link>

<link name="body_2_2_1">
  <inertial>
    <origin xyz="-0.04311 0.170506 0.095064" rpy="0 0 0"/>
    <mass value="0.1049739427457743"/>
    <inertia ixx="0.00012607278005472792" iyy="0.00012089434645677936" izz="0.0001392166320821264" ixy="1.1985563518274525e-06" iyz="-7.295824618270413e-06" ixz="2.2235790760200382e-05"/>
  </inertial>
  <visual>
    <origin xyz="-0.04311 0.170506 0.095064" rpy="0 0 0"/>
    <geometry>
      <mesh filename="simple_meshes/body_2_2_1.stl" scale="0.001 0.001 0.001"/>
    </geometry>
    <material name="pla_5_percent_infill"/>
  </visual>
  <collision>
    <origin xyz="-0.04311 0.170506 0.095064" rpy="0 0 0"/>
    <geometry>
      <mesh filename="simple_meshes/body_2_2_1.stl" scale="0.001 0.001 0.001"/>
    </geometry>
  </collision>
</link>

<link name="body_2_3_1">
  <inertial>
    <origin xyz="0.129712 0.175384 0.095064" rpy="0 0 0"/>
    <mass value="0.10880476385839909"/>
    <inertia ixx="0.00013398873835935698" iyy="0.00013065003356161915" izz="0.0001344310452533956" ixy="6.674114086635454e-06" iyz="-2.394213149508684e-05" ixz="3.567788191607404e-05"/>
  </inertial>
  <visual>
    <origin xyz="0.129712 0.175384 0.095064" rpy="0 0 0"/>
    <geometry>
      <mesh filename="simple_meshes/body_2_3_1.stl" scale="0.001 0.001 0.001"/>
    </geometry>
    <material name="pla_5_percent_infill"/>
  </visual>
  <collision>
    <origin xyz="0.129712 0.175384 0.095064" rpy="0 0 0"/>
    <geometry>
      <mesh filename="simple_meshes/body_2_3_1.stl" scale="0.001 0.001 0.001"/>
    </geometry>
  </collision>
</link>

<joint name="joint_1_0" type="revolute">
  <origin xyz="0.045735 0.109621 0.00462" rpy="0 0 0"/>
  <parent link="base_link"/>
  <child link="body_1_0_1"/>
  <axis xyz="0.0 1.0 0.0"/>
  <limit upper="1.2" lower="-1.2" effort="3.8" velocity="5.4"/>
</joint>
<transmission name="joint_1_0_tran">
  <type>transmission_interface/SimpleTransmission</type>
  <joint name="joint_1_0">
    <hardwareInterface>PositionJointInterface</hardwareInterface>
  </joint>
  <actuator name="joint_1_0_actr">
    <hardwareInterface>PositionJointInterface</hardwareInterface>
    <mechanicalReduction>1</mechanicalReduction>
  </actuator>
</transmission>

<joint name="joint_1_1" type="revolute">
  <origin xyz="-0.086489 0.109621 0.018802" rpy="0 0 0"/>
  <parent link="base_link"/>
  <child link="body_1_1_1"/>
  <axis xyz="0.0 1.0 0.0"/>
  <limit upper="1.2" lower="-1.2" effort="3.8" velocity="5.4"/>
</joint>
<transmission name="joint_1_1_tran">
  <type>transmission_interface/SimpleTransmission</type>
  <joint name="joint_1_1">
    <hardwareInterface>PositionJointInterface</hardwareInterface>
  </joint>
  <actuator name="joint_1_1_actr">
    <hardwareInterface>PositionJointInterface</hardwareInterface>
    <mechanicalReduction>1</mechanicalReduction>
  </actuator>
</transmission>

<joint name="joint_1_2" type="revolute">
  <origin xyz="0.040267 -0.109621 0.027764" rpy="0 0 0"/>
  <parent link="base_link"/>
  <child link="body_1_2_1"/>
  <axis xyz="0.0 1.0 0.0"/>
  <limit upper="1.2" lower="-1.2" effort="3.8" velocity="5.4"/>
</joint>
<transmission name="joint_1_2_tran">
  <type>transmission_interface/SimpleTransmission</type>
  <joint name="joint_1_2">
    <hardwareInterface>PositionJointInterface</hardwareInterface>
  </joint>
  <actuator name="joint_1_2_actr">
    <hardwareInterface>PositionJointInterface</hardwareInterface>
    <mechanicalReduction>1</mechanicalReduction>
  </actuator>
</transmission>

<joint name="joint_1_3" type="revolute">
  <origin xyz="-0.090407 -0.109621 0.022193" rpy="0 0 0"/>
  <parent link="base_link"/>
  <child link="body_1_3_1"/>
  <axis xyz="0.0 1.0 0.0"/>
  <limit upper="1.2" lower="-1.2" effort="3.8" velocity="5.4"/>
</joint>
<transmission name="joint_1_3_tran">
  <type>transmission_interface/SimpleTransmission</type>
  <joint name="joint_1_3">
    <hardwareInterface>PositionJointInterface</hardwareInterface>
  </joint>
  <actuator name="joint_1_3_actr">
    <hardwareInterface>PositionJointInterface</hardwareInterface>
    <mechanicalReduction>1</mechanicalReduction>
  </actuator>
</transmission>

<joint name="joint_2_0" type="revolute">
  <origin xyz="0.003827 0.050176 -0.099684" rpy="0 0 0"/>
  <parent link="body_1_0_1"/>
  <child link="body_2_0_1"/>
  <axis xyz="0.0 0.0 1.0"/>
  <limit upper="1.2" lower="-1.2" effort="3.8" velocity="5.4"/>
</joint>
<transmission name="joint_2_0_tran">
  <type>transmission_interface/SimpleTransmission</type>
  <joint name="joint_2_0">
    <hardwareInterface>PositionJointInterface</hardwareInterface>
  </joint>
  <actuator name="joint_2_0_actr">
    <hardwareInterface>PositionJointInterface</hardwareInterface>
    <mechanicalReduction>1</mechanicalReduction>
  </actuator>
</transmission>

<joint name="joint_2_1" type="revolute">
  <origin xyz="-0.034693 0.064331 -0.113866" rpy="0 0 0"/>
  <parent link="body_1_1_1"/>
  <child link="body_2_1_1"/>
  <axis xyz="0.0 0.0 1.0"/>
  <limit upper="1.2" lower="-1.2" effort="3.8" velocity="5.4"/>
</joint>
<transmission name="joint_2_1_tran">
  <type>transmission_interface/SimpleTransmission</type>
  <joint name="joint_2_1">
    <hardwareInterface>PositionJointInterface</hardwareInterface>
  </joint>
  <actuator name="joint_2_1_actr">
    <hardwareInterface>PositionJointInterface</hardwareInterface>
    <mechanicalReduction>1</mechanicalReduction>
  </actuator>
</transmission>

<joint name="joint_2_2" type="revolute">
  <origin xyz="0.002843 -0.060885 -0.122828" rpy="0 0 0"/>
  <parent link="body_1_2_1"/>
  <child link="body_2_2_1"/>
  <axis xyz="0.0 0.0 1.0"/>
  <limit upper="1.2" lower="-1.2" effort="3.8" velocity="5.4"/>
</joint>
<transmission name="joint_2_2_tran">
  <type>transmission_interface/SimpleTransmission</type>
  <joint name="joint_2_2">
    <hardwareInterface>PositionJointInterface</hardwareInterface>
  </joint>
  <actuator name="joint_2_2_actr">
    <hardwareInterface>PositionJointInterface</hardwareInterface>
    <mechanicalReduction>1</mechanicalReduction>
  </actuator>
</transmission>

<joint name="joint_2_3" type="revolute">
  <origin xyz="-0.039305 -0.065763 -0.117257" rpy="0 0 0"/>
  <parent link="body_1_3_1"/>
  <child link="body_2_3_1"/>
  <axis xyz="0.0 0.0 1.0"/>
  <limit upper="1.2" lower="-1.2" effort="3.8" velocity="5.4"/>
</joint>
<transmission name="joint_2_3_tran">
  <type>transmission_interface/SimpleTransmission</type>
  <joint name="joint_2_3">
    <hardwareInterface>PositionJointInterface</hardwareInterface>
  </joint>
  <actuator name="joint_2_3_actr">
    <hardwareInterface>PositionJointInterface</hardwareInterface>
    <mechanicalReduction>1</mechanicalReduction>
  </actuator>
</transmission>

</robot>
